[05/Jul/2017 17:55:53] "GET / HTTP/1.0" 200 6353
[05/Jul/2017 17:55:55] "POST /login HTTP/1.0" 302 0
[05/Jul/2017 17:55:55] "GET /im_list.html HTTP/1.0" 200 5283
Not Found: /admin
Not Found: /admin
[05/Jul/2017 17:56:46] "GET /admin HTTP/1.0" 301 0
[05/Jul/2017 17:56:46] "GET /admin/ HTTP/1.0" 302 0
[05/Jul/2017 17:56:47] "GET /admin/login/?next=/admin/ HTTP/1.0" 200 1834
[05/Jul/2017 17:56:49] "POST /admin/login/?next=/admin/ HTTP/1.0" 200 1994
[05/Jul/2017 17:56:55] "POST /admin/login/?next=/admin/ HTTP/1.0" 200 1994
[05/Jul/2017 17:57:43] "POST /admin/login/?next=/admin/ HTTP/1.0" 302 0
[05/Jul/2017 17:57:43] "GET /admin/ HTTP/1.0" 200 3403
[05/Jul/2017 17:57:48] "GET /admin/video/nav/ HTTP/1.0" 200 5650
[05/Jul/2017 17:57:48] "GET /admin/jsi18n/ HTTP/1.0" 200 3217
/www/web/django_video/env/lib/python2.7/site-packages/django/forms/widgets.py:262: UnicodeWarning: Unicode unequal comparison failed to convert both arguments to Unicode - interpreting them as being unequal
  if value != '':

/www/web/django_video/env/lib/python2.7/site-packages/django/forms/widgets.py:262: UnicodeWarning: Unicode unequal comparison failed to convert both arguments to Unicode - interpreting them as being unequal
  if value != '':

[05/Jul/2017 17:57:53] "GET /admin/video/nav/add/ HTTP/1.0" 200 8190
[05/Jul/2017 17:57:53] "GET /admin/jsi18n/ HTTP/1.0" 200 3217
[05/Jul/2017 18:00:13] "POST /admin/video/nav/add/ HTTP/1.0" 302 0
[05/Jul/2017 18:00:13] "GET /admin/video/nav/ HTTP/1.0" 200 6021
[05/Jul/2017 18:00:13] "GET /admin/jsi18n/ HTTP/1.0" 200 3217
[05/Jul/2017 18:00:23] "GET / HTTP/1.0" 200 6894
Internal Server Error: /upload
Traceback (most recent call last):
  File "/www/web/django_video/env/lib/python2.7/site-packages/django/core/handlers/base.py", line 149, in get_response
    response = self.process_exception_by_middleware(e, request)
  File "/www/web/django_video/env/lib/python2.7/site-packages/django/core/handlers/base.py", line 147, in get_response
    response = wrapped_callback(request, *callback_args, **callback_kwargs)
  File "/www/web/django_video/video_omsa/video/views.py", line 149, in upload
    form = NewForm(request.GET)
NameError: global name 'NewForm' is not defined
Internal Server Error: /upload
Traceback (most recent call last):
  File "/www/web/django_video/env/lib/python2.7/site-packages/django/core/handlers/base.py", line 149, in get_response
    response = self.process_exception_by_middleware(e, request)
  File "/www/web/django_video/env/lib/python2.7/site-packages/django/core/handlers/base.py", line 147, in get_response
    response = wrapped_callback(request, *callback_args, **callback_kwargs)
  File "/www/web/django_video/video_omsa/video/views.py", line 149, in upload
    form = NewForm(request.GET)
NameError: global name 'NewForm' is not defined
[05/Jul/2017 18:00:27] "GET /upload HTTP/1.0" 500 66016
Internal Server Error: /inters_data
Traceback (most recent call last):
  File "/www/web/django_video/env/lib/python2.7/site-packages/django/core/handlers/base.py", line 149, in get_response
    response = self.process_exception_by_middleware(e, request)
  File "/www/web/django_video/env/lib/python2.7/site-packages/django/core/handlers/base.py", line 147, in get_response
    response = wrapped_callback(request, *callback_args, **callback_kwargs)
  File "/www/web/django_video/video_omsa/video/views.py", line 167, in inters_data
    form = intersForm(request.GET)
NameError: global name 'intersForm' is not defined
Internal Server Error: /inters_data
Traceback (most recent call last):
  File "/www/web/django_video/env/lib/python2.7/site-packages/django/core/handlers/base.py", line 149, in get_response
    response = self.process_exception_by_middleware(e, request)
  File "/www/web/django_video/env/lib/python2.7/site-packages/django/core/handlers/base.py", line 147, in get_response
    response = wrapped_callback(request, *callback_args, **callback_kwargs)
  File "/www/web/django_video/video_omsa/video/views.py", line 167, in inters_data
    form = intersForm(request.GET)
NameError: global name 'intersForm' is not defined
[05/Jul/2017 18:01:55] "GET /inters_data HTTP/1.0" 500 66765
Performing system checks...

System check identified no issues (0 silenced).
July 05, 2017 - 17:55:46
Django version 1.9, using settings 'video_omsa.settings'
Starting development server at http://0.0.0.0:88/
Quit the server with CONTROL-C.
Unhandled exception in thread started by <function wrapper at 0x24521b8>
Performing system checks...

Traceback (most recent call last):
  File "/www/web/django_video/env/lib/python2.7/site-packages/django/utils/autoreload.py", line 226, in wrapper
    fn(*args, **kwargs)
  File "/www/web/django_video/env/lib/python2.7/site-packages/django/core/management/commands/runserver.py", line 116, in inner_run
    self.check(display_num_errors=True)
  File "/www/web/django_video/env/lib/python2.7/site-packages/django/core/management/base.py", line 426, in check
    include_deployment_checks=include_deployment_checks,
  File "/www/web/django_video/env/lib/python2.7/site-packages/django/core/checks/registry.py", line 75, in run_checks
    new_errors = check(app_configs=app_configs)
  File "/www/web/django_video/env/lib/python2.7/site-packages/django/core/checks/urls.py", line 10, in check_url_config
    return check_resolver(resolver)
  File "/www/web/django_video/env/lib/python2.7/site-packages/django/core/checks/urls.py", line 19, in check_resolver
    for pattern in resolver.url_patterns:
  File "/www/web/django_video/env/lib/python2.7/site-packages/django/utils/functional.py", line 33, in __get__
    res = instance.__dict__[self.name] = self.func(instance)
  File "/www/web/django_video/env/lib/python2.7/site-packages/django/core/urlresolvers.py", line 417, in url_patterns
    patterns = getattr(self.urlconf_module, "urlpatterns", self.urlconf_module)
  File "/www/web/django_video/env/lib/python2.7/site-packages/django/utils/functional.py", line 33, in __get__
    res = instance.__dict__[self.name] = self.func(instance)
  File "/www/web/django_video/env/lib/python2.7/site-packages/django/core/urlresolvers.py", line 410, in urlconf_module
    return import_module(self.urlconf_name)
  File "/usr/lib64/python2.7/importlib/__init__.py", line 37, in import_module
    __import__(name)
  File "/www/web/django_video/video_omsa/video_omsa/urls.py", line 5, in <module>
    from video import views as video_views
  File "/www/web/django_video/video_omsa/video/views.py", line 9, in <module>
    from video.forms import videoForm,LoginForm,registerForm,ImEditForm
  File "/www/web/django_video/video_omsa/video/forms.py", line 73, in <module>
    class intersForm(forms.Form):
  File "/www/web/django_video/video_omsa/video/forms.py", line 74, in intersForm
    date = forms.DateField(label='请选择日期',widget=SelectDateWidget(years=YEARS_CHOICES))
NameError: name 'SelectDateWidget' is not defined
Unhandled exception in thread started by <function wrapper at 0x219b1b8>
Performing system checks...

Traceback (most recent call last):
  File "/www/web/django_video/env/lib/python2.7/site-packages/django/utils/autoreload.py", line 226, in wrapper
    fn(*args, **kwargs)
  File "/www/web/django_video/env/lib/python2.7/site-packages/django/core/management/commands/runserver.py", line 116, in inner_run
    self.check(display_num_errors=True)
  File "/www/web/django_video/env/lib/python2.7/site-packages/django/core/management/base.py", line 426, in check
    include_deployment_checks=include_deployment_checks,
  File "/www/web/django_video/env/lib/python2.7/site-packages/django/core/checks/registry.py", line 75, in run_checks
    new_errors = check(app_configs=app_configs)
  File "/www/web/django_video/env/lib/python2.7/site-packages/django/core/checks/urls.py", line 10, in check_url_config
    return check_resolver(resolver)
  File "/www/web/django_video/env/lib/python2.7/site-packages/django/core/checks/urls.py", line 19, in check_resolver
    for pattern in resolver.url_patterns:
  File "/www/web/django_video/env/lib/python2.7/site-packages/django/utils/functional.py", line 33, in __get__
    res = instance.__dict__[self.name] = self.func(instance)
  File "/www/web/django_video/env/lib/python2.7/site-packages/django/core/urlresolvers.py", line 417, in url_patterns
    patterns = getattr(self.urlconf_module, "urlpatterns", self.urlconf_module)
  File "/www/web/django_video/env/lib/python2.7/site-packages/django/utils/functional.py", line 33, in __get__
    res = instance.__dict__[self.name] = self.func(instance)
  File "/www/web/django_video/env/lib/python2.7/site-packages/django/core/urlresolvers.py", line 410, in urlconf_module
    return import_module(self.urlconf_name)
  File "/usr/lib64/python2.7/importlib/__init__.py", line 37, in import_module
    __import__(name)
  File "/www/web/django_video/video_omsa/video_omsa/urls.py", line 5, in <module>
    from video import views as video_views
  File "/www/web/django_video/video_omsa/video/views.py", line 9, in <module>
    from video.forms import videoForm,LoginForm,registerForm,ImEditForm
  File "/www/web/django_video/video_omsa/video/forms.py", line 77, in <module>
    class intersForm(forms.Form):
  File "/www/web/django_video/video_omsa/video/forms.py", line 78, in intersForm
    date = forms.DateField(label='请选择日期',widget=SelectDateWidget(years=YEARS_CHOICES))
NameError: name 'SelectDateWidget' is not defined
Unhandled exception in thread started by <function wrapper at 0x2ecd1b8>
Performing system checks...

Traceback (most recent call last):
  File "/www/web/django_video/env/lib/python2.7/site-packages/django/utils/autoreload.py", line 226, in wrapper
    fn(*args, **kwargs)
  File "/www/web/django_video/env/lib/python2.7/site-packages/django/core/management/commands/runserver.py", line 116, in inner_run
    self.check(display_num_errors=True)
  File "/www/web/django_video/env/lib/python2.7/site-packages/django/core/management/base.py", line 426, in check
    include_deployment_checks=include_deployment_checks,
  File "/www/web/django_video/env/lib/python2.7/site-packages/django/core/checks/registry.py", line 75, in run_checks
    new_errors = check(app_configs=app_configs)
  File "/www/web/django_video/env/lib/python2.7/site-packages/django/core/checks/urls.py", line 10, in check_url_config
    return check_resolver(resolver)
  File "/www/web/django_video/env/lib/python2.7/site-packages/django/core/checks/urls.py", line 19, in check_resolver
    for pattern in resolver.url_patterns:
  File "/www/web/django_video/env/lib/python2.7/site-packages/django/utils/functional.py", line 33, in __get__
    res = instance.__dict__[self.name] = self.func(instance)
  File "/www/web/django_video/env/lib/python2.7/site-packages/django/core/urlresolvers.py", line 417, in url_patterns
    patterns = getattr(self.urlconf_module, "urlpatterns", self.urlconf_module)
  File "/www/web/django_video/env/lib/python2.7/site-packages/django/utils/functional.py", line 33, in __get__
    res = instance.__dict__[self.name] = self.func(instance)
  File "/www/web/django_video/env/lib/python2.7/site-packages/django/core/urlresolvers.py", line 410, in urlconf_module
    return import_module(self.urlconf_name)
  File "/usr/lib64/python2.7/importlib/__init__.py", line 37, in import_module
    __import__(name)
  File "/www/web/django_video/video_omsa/video_omsa/urls.py", line 5, in <module>
    from video import views as video_views
  File "/www/web/django_video/video_omsa/video/views.py", line 9, in <module>
    from video.forms import videoForm,LoginForm,registerForm,ImEditForm,NewForm,intersForm
  File "/www/web/django_video/video_omsa/video/forms.py", line 83, in <module>
    class NewForm(forms.Form):
  File "/www/web/django_video/video_omsa/video/forms.py", line 86, in NewForm
    phone = forms.CharField(validators=[PhoneValidate,],error_messages={'required':'手机号码不能为空'},
NameError: name 'PhoneValidate' is not defined
[05/Jul/2017 18:05:43] "GET / HTTP/1.0" 200 6894
Internal Server Error: /upload
Traceback (most recent call last):
  File "/www/web/django_video/env/lib/python2.7/site-packages/django/core/handlers/base.py", line 149, in get_response
    response = self.process_exception_by_middleware(e, request)
  File "/www/web/django_video/env/lib/python2.7/site-packages/django/core/handlers/base.py", line 147, in get_response
    response = wrapped_callback(request, *callback_args, **callback_kwargs)
  File "/www/web/django_video/video_omsa/video/views.py", line 150, in upload
    return render(request,'upload.html')
  File "/www/web/django_video/env/lib/python2.7/site-packages/django/shortcuts.py", line 67, in render
    template_name, context, request=request, using=using)
  File "/www/web/django_video/env/lib/python2.7/site-packages/django/template/loader.py", line 96, in render_to_string
    template = get_template(template_name, using=using)
  File "/www/web/django_video/env/lib/python2.7/site-packages/django/template/loader.py", line 43, in get_template
    raise TemplateDoesNotExist(template_name, chain=chain)
TemplateDoesNotExist: upload.html
Internal Server Error: /upload
Traceback (most recent call last):
  File "/www/web/django_video/env/lib/python2.7/site-packages/django/core/handlers/base.py", line 149, in get_response
    response = self.process_exception_by_middleware(e, request)
  File "/www/web/django_video/env/lib/python2.7/site-packages/django/core/handlers/base.py", line 147, in get_response
    response = wrapped_callback(request, *callback_args, **callback_kwargs)
  File "/www/web/django_video/video_omsa/video/views.py", line 150, in upload
    return render(request,'upload.html')
  File "/www/web/django_video/env/lib/python2.7/site-packages/django/shortcuts.py", line 67, in render
    template_name, context, request=request, using=using)
  File "/www/web/django_video/env/lib/python2.7/site-packages/django/template/loader.py", line 96, in render_to_string
    template = get_template(template_name, using=using)
  File "/www/web/django_video/env/lib/python2.7/site-packages/django/template/loader.py", line 43, in get_template
    raise TemplateDoesNotExist(template_name, chain=chain)
TemplateDoesNotExist: upload.html
[05/Jul/2017 18:05:46] "GET /upload HTTP/1.0" 500 82914
[05/Jul/2017 18:07:08] "GET /upload HTTP/1.0" 200 1919
[05/Jul/2017 18:07:14] "GET /inters_data HTTP/1.0" 200 6884
[05/Jul/2017 18:07:21] "GET /add HTTP/1.0" 200 2455
[05/Jul/2017 18:07:58] "POST /login HTTP/1.0" 302 0
[05/Jul/2017 18:07:58] "GET /im_list.html HTTP/1.0" 200 5826
[05/Jul/2017 18:08:06] "GET /inters_data HTTP/1.0" 200 6884
[05/Jul/2017 18:08:15] "POST /inters_data HTTP/1.0" 200 6995
[05/Jul/2017 18:08:18] "POST /inters_data HTTP/1.0" 200 6995
[05/Jul/2017 18:08:19] "POST /inters_data HTTP/1.0" 200 6995
[05/Jul/2017 18:08:27] "POST /inters_data HTTP/1.0" 200 6995
[05/Jul/2017 18:08:31] "POST /inters_data HTTP/1.0" 200 6995
[05/Jul/2017 18:08:31] "POST /inters_data HTTP/1.0" 200 6995
[05/Jul/2017 18:08:32] "POST /inters_data HTTP/1.0" 200 6995
[05/Jul/2017 18:08:32] "POST /inters_data HTTP/1.0" 200 6995
[05/Jul/2017 18:08:33] "POST /inters_data HTTP/1.0" 200 6995
[05/Jul/2017 18:08:58] "POST /inters_data HTTP/1.0" 200 6995
[05/Jul/2017 18:08:59] "POST /inters_data HTTP/1.0" 200 6995
[05/Jul/2017 18:09:08] "POST /inters_data HTTP/1.0" 200 6995
[05/Jul/2017 18:09:08] "POST /inters_data HTTP/1.0" 200 6995
[05/Jul/2017 18:09:09] "POST /inters_data HTTP/1.0" 200 6995
[05/Jul/2017 18:09:09] "POST /inters_data HTTP/1.0" 200 6995
[05/Jul/2017 18:10:04] "POST /inters_data HTTP/1.0" 200 6995
[05/Jul/2017 18:10:05] "POST /inters_data HTTP/1.0" 200 6995
[05/Jul/2017 18:10:05] "POST /inters_data HTTP/1.0" 200 6995
[05/Jul/2017 18:11:24] "GET /inters_data HTTP/1.0" 200 6884
[05/Jul/2017 18:11:25] "GET /im_list.html HTTP/1.0" 200 5826
[05/Jul/2017 18:11:25] "GET / HTTP/1.0" 200 6894
[05/Jul/2017 18:42:31] "POST /login HTTP/1.0" 302 0
[05/Jul/2017 18:42:31] "GET /im_list.html HTTP/1.0" 200 5826
[05/Jul/2017 19:22:41] "GET / HTTP/1.0" 200 6894
[05/Jul/2017 21:39:32] "GET / HTTP/1.0" 200 6894
Not Found: /favicon.ico
Not Found: /favicon.ico
[05/Jul/2017 21:39:35] "GET /favicon.ico HTTP/1.0" 404 3828
[05/Jul/2017 21:39:38] "GET /upload HTTP/1.0" 200 1919
Internal Server Error: /up_recive
Traceback (most recent call last):
  File "/www/web/django_video/env/lib/python2.7/site-packages/django/core/handlers/base.py", line 149, in get_response
    response = self.process_exception_by_middleware(e, request)
  File "/www/web/django_video/env/lib/python2.7/site-packages/django/core/handlers/base.py", line 147, in get_response
    response = wrapped_callback(request, *callback_args, **callback_kwargs)
  File "/www/web/django_video/video_omsa/video/views.py", line 157, in up_recive
    save_destination = open(os.path.join("uploads",files.name),'wb+') # 打开特定的文件进行二进制写操作
NameError: global name 'os' is not defined
Internal Server Error: /up_recive
Traceback (most recent call last):
  File "/www/web/django_video/env/lib/python2.7/site-packages/django/core/handlers/base.py", line 149, in get_response
    response = self.process_exception_by_middleware(e, request)
  File "/www/web/django_video/env/lib/python2.7/site-packages/django/core/handlers/base.py", line 147, in get_response
    response = wrapped_callback(request, *callback_args, **callback_kwargs)
  File "/www/web/django_video/video_omsa/video/views.py", line 157, in up_recive
    save_destination = open(os.path.join("uploads",files.name),'wb+') # 打开特定的文件进行二进制写操作
NameError: global name 'os' is not defined
[05/Jul/2017 21:39:59] "POST /up_recive HTTP/1.0" 500 67584
Internal Server Error: /
Traceback (most recent call last):
  File "/www/web/django_video/env/lib/python2.7/site-packages/django/core/handlers/base.py", line 149, in get_response
    response = self.process_exception_by_middleware(e, request)
  File "/www/web/django_video/env/lib/python2.7/site-packages/django/core/handlers/base.py", line 147, in get_response
    response = wrapped_callback(request, *callback_args, **callback_kwargs)
  File "/www/web/django_video/video_omsa/video/views.py", line 98, in index
    navs = list(Nav.objects.all())
  File "/www/web/django_video/env/lib/python2.7/site-packages/django/db/models/query.py", line 258, in __iter__
    self._fetch_all()
  File "/www/web/django_video/env/lib/python2.7/site-packages/django/db/models/query.py", line 1074, in _fetch_all
    self._result_cache = list(self.iterator())
  File "/www/web/django_video/env/lib/python2.7/site-packages/django/db/models/query.py", line 52, in __iter__
    results = compiler.execute_sql()
  File "/www/web/django_video/env/lib/python2.7/site-packages/django/db/models/sql/compiler.py", line 850, in execute_sql
    cursor = self.connection.cursor()
  File "/www/web/django_video/env/lib/python2.7/site-packages/django/db/backends/base/base.py", line 231, in cursor
    cursor = self.make_debug_cursor(self._cursor())
  File "/www/web/django_video/env/lib/python2.7/site-packages/django/db/backends/base/base.py", line 204, in _cursor
    self.ensure_connection()
  File "/www/web/django_video/env/lib/python2.7/site-packages/django/db/backends/base/base.py", line 199, in ensure_connection
    self.connect()
  File "/www/web/django_video/env/lib/python2.7/site-packages/django/db/utils.py", line 95, in __exit__
    six.reraise(dj_exc_type, dj_exc_value, traceback)
  File "/www/web/django_video/env/lib/python2.7/site-packages/django/db/backends/base/base.py", line 199, in ensure_connection
    self.connect()
  File "/www/web/django_video/env/lib/python2.7/site-packages/django/db/backends/base/base.py", line 171, in connect
    self.connection = self.get_new_connection(conn_params)
  File "/www/web/django_video/env/lib/python2.7/site-packages/django/db/backends/mysql/base.py", line 264, in get_new_connection
    conn = Database.connect(**conn_params)
  File "/www/web/django_video/env/lib/python2.7/site-packages/MySQLdb/__init__.py", line 81, in Connect
    return Connection(*args, **kwargs)
  File "/www/web/django_video/env/lib/python2.7/site-packages/MySQLdb/connections.py", line 193, in __init__
    super(Connection, self).__init__(*args, **kwargs2)
OperationalError: (2002, "Can't connect to local MySQL server through socket '/var/lib/mysql/mysql.sock' (2)")
Internal Server Error: /
Traceback (most recent call last):
  File "/www/web/django_video/env/lib/python2.7/site-packages/django/core/handlers/base.py", line 149, in get_response
    response = self.process_exception_by_middleware(e, request)
  File "/www/web/django_video/env/lib/python2.7/site-packages/django/core/handlers/base.py", line 147, in get_response
    response = wrapped_callback(request, *callback_args, **callback_kwargs)
  File "/www/web/django_video/video_omsa/video/views.py", line 98, in index
    navs = list(Nav.objects.all())
  File "/www/web/django_video/env/lib/python2.7/site-packages/django/db/models/query.py", line 258, in __iter__
    self._fetch_all()
  File "/www/web/django_video/env/lib/python2.7/site-packages/django/db/models/query.py", line 1074, in _fetch_all
    self._result_cache = list(self.iterator())
  File "/www/web/django_video/env/lib/python2.7/site-packages/django/db/models/query.py", line 52, in __iter__
    results = compiler.execute_sql()
  File "/www/web/django_video/env/lib/python2.7/site-packages/django/db/models/sql/compiler.py", line 850, in execute_sql
    cursor = self.connection.cursor()
  File "/www/web/django_video/env/lib/python2.7/site-packages/django/db/backends/base/base.py", line 231, in cursor
    cursor = self.make_debug_cursor(self._cursor())
  File "/www/web/django_video/env/lib/python2.7/site-packages/django/db/backends/base/base.py", line 204, in _cursor
    self.ensure_connection()
  File "/www/web/django_video/env/lib/python2.7/site-packages/django/db/backends/base/base.py", line 199, in ensure_connection
    self.connect()
  File "/www/web/django_video/env/lib/python2.7/site-packages/django/db/utils.py", line 95, in __exit__
    six.reraise(dj_exc_type, dj_exc_value, traceback)
  File "/www/web/django_video/env/lib/python2.7/site-packages/django/db/backends/base/base.py", line 199, in ensure_connection
    self.connect()
  File "/www/web/django_video/env/lib/python2.7/site-packages/django/db/backends/base/base.py", line 171, in connect
    self.connection = self.get_new_connection(conn_params)
  File "/www/web/django_video/env/lib/python2.7/site-packages/django/db/backends/mysql/base.py", line 264, in get_new_connection
    conn = Database.connect(**conn_params)
  File "/www/web/django_video/env/lib/python2.7/site-packages/MySQLdb/__init__.py", line 81, in Connect
    return Connection(*args, **kwargs)
  File "/www/web/django_video/env/lib/python2.7/site-packages/MySQLdb/connections.py", line 193, in __init__
    super(Connection, self).__init__(*args, **kwargs2)
OperationalError: (2002, "Can't connect to local MySQL server through socket '/var/lib/mysql/mysql.sock' (2)")
Internal Server Error: /
Traceback (most recent call last):
  File "/www/web/django_video/env/lib/python2.7/site-packages/django/core/handlers/base.py", line 149, in get_response
    response = self.process_exception_by_middleware(e, request)
  File "/www/web/django_video/env/lib/python2.7/site-packages/django/core/handlers/base.py", line 147, in get_response
    response = wrapped_callback(request, *callback_args, **callback_kwargs)
  File "/www/web/django_video/video_omsa/video/views.py", line 98, in index
    navs = list(Nav.objects.all())
  File "/www/web/django_video/env/lib/python2.7/site-packages/django/db/models/query.py", line 258, in __iter__
    self._fetch_all()
  File "/www/web/django_video/env/lib/python2.7/site-packages/django/db/models/query.py", line 1074, in _fetch_all
    self._result_cache = list(self.iterator())
  File "/www/web/django_video/env/lib/python2.7/site-packages/django/db/models/query.py", line 52, in __iter__
    results = compiler.execute_sql()
  File "/www/web/django_video/env/lib/python2.7/site-packages/django/db/models/sql/compiler.py", line 850, in execute_sql
    cursor = self.connection.cursor()
  File "/www/web/django_video/env/lib/python2.7/site-packages/django/db/backends/base/base.py", line 231, in cursor
    cursor = self.make_debug_cursor(self._cursor())
  File "/www/web/django_video/env/lib/python2.7/site-packages/django/db/backends/base/base.py", line 204, in _cursor
    self.ensure_connection()
  File "/www/web/django_video/env/lib/python2.7/site-packages/django/db/backends/base/base.py", line 199, in ensure_connection
    self.connect()
  File "/www/web/django_video/env/lib/python2.7/site-packages/django/db/utils.py", line 95, in __exit__
    six.reraise(dj_exc_type, dj_exc_value, traceback)
  File "/www/web/django_video/env/lib/python2.7/site-packages/django/db/backends/base/base.py", line 199, in ensure_connection
    self.connect()
  File "/www/web/django_video/env/lib/python2.7/site-packages/django/db/backends/base/base.py", line 171, in connect
    self.connection = self.get_new_connection(conn_params)
  File "/www/web/django_video/env/lib/python2.7/site-packages/django/db/backends/mysql/base.py", line 264, in get_new_connection
    conn = Database.connect(**conn_params)
  File "/www/web/django_video/env/lib/python2.7/site-packages/MySQLdb/__init__.py", line 81, in Connect
    return Connection(*args, **kwargs)
  File "/www/web/django_video/env/lib/python2.7/site-packages/MySQLdb/connections.py", line 193, in __init__
    super(Connection, self).__init__(*args, **kwargs2)
OperationalError: (2002, "Can't connect to local MySQL server through socket '/var/lib/mysql/mysql.sock' (2)")
Internal Server Error: /
Traceback (most recent call last):
  File "/www/web/django_video/env/lib/python2.7/site-packages/django/core/handlers/base.py", line 149, in get_response
    response = self.process_exception_by_middleware(e, request)
  File "/www/web/django_video/env/lib/python2.7/site-packages/django/core/handlers/base.py", line 147, in get_response
    response = wrapped_callback(request, *callback_args, **callback_kwargs)
  File "/www/web/django_video/video_omsa/video/views.py", line 98, in index
    navs = list(Nav.objects.all())
  File "/www/web/django_video/env/lib/python2.7/site-packages/django/db/models/query.py", line 258, in __iter__
    self._fetch_all()
  File "/www/web/django_video/env/lib/python2.7/site-packages/django/db/models/query.py", line 1074, in _fetch_all
    self._result_cache = list(self.iterator())
  File "/www/web/django_video/env/lib/python2.7/site-packages/django/db/models/query.py", line 52, in __iter__
    results = compiler.execute_sql()
  File "/www/web/django_video/env/lib/python2.7/site-packages/django/db/models/sql/compiler.py", line 850, in execute_sql
    cursor = self.connection.cursor()
  File "/www/web/django_video/env/lib/python2.7/site-packages/django/db/backends/base/base.py", line 231, in cursor
    cursor = self.make_debug_cursor(self._cursor())
  File "/www/web/django_video/env/lib/python2.7/site-packages/django/db/backends/base/base.py", line 204, in _cursor
    self.ensure_connection()
  File "/www/web/django_video/env/lib/python2.7/site-packages/django/db/backends/base/base.py", line 199, in ensure_connection
    self.connect()
  File "/www/web/django_video/env/lib/python2.7/site-packages/django/db/utils.py", line 95, in __exit__
    six.reraise(dj_exc_type, dj_exc_value, traceback)
  File "/www/web/django_video/env/lib/python2.7/site-packages/django/db/backends/base/base.py", line 199, in ensure_connection
    self.connect()
  File "/www/web/django_video/env/lib/python2.7/site-packages/django/db/backends/base/base.py", line 171, in connect
    self.connection = self.get_new_connection(conn_params)
  File "/www/web/django_video/env/lib/python2.7/site-packages/django/db/backends/mysql/base.py", line 264, in get_new_connection
    conn = Database.connect(**conn_params)
  File "/www/web/django_video/env/lib/python2.7/site-packages/MySQLdb/__init__.py", line 81, in Connect
    return Connection(*args, **kwargs)
  File "/www/web/django_video/env/lib/python2.7/site-packages/MySQLdb/connections.py", line 193, in __init__
    super(Connection, self).__init__(*args, **kwargs2)
OperationalError: (2002, "Can't connect to local MySQL server through socket '/var/lib/mysql/mysql.sock' (2)")
[05/Jul/2017 21:58:36] "GET / HTTP/1.0" 500 139837
- Broken pipe from ('127.0.0.1', 46552)
[05/Jul/2017 21:58:42] "GET / HTTP/1.0" 500 140073
- Broken pipe from ('127.0.0.1', 46554)
Internal Server Error: /
Traceback (most recent call last):
  File "/www/web/django_video/env/lib/python2.7/site-packages/django/core/handlers/base.py", line 149, in get_response
    response = self.process_exception_by_middleware(e, request)
  File "/www/web/django_video/env/lib/python2.7/site-packages/django/core/handlers/base.py", line 147, in get_response
    response = wrapped_callback(request, *callback_args, **callback_kwargs)
  File "/www/web/django_video/video_omsa/video/views.py", line 98, in index
    navs = list(Nav.objects.all())
  File "/www/web/django_video/env/lib/python2.7/site-packages/django/db/models/query.py", line 258, in __iter__
    self._fetch_all()
  File "/www/web/django_video/env/lib/python2.7/site-packages/django/db/models/query.py", line 1074, in _fetch_all
    self._result_cache = list(self.iterator())
  File "/www/web/django_video/env/lib/python2.7/site-packages/django/db/models/query.py", line 52, in __iter__
    results = compiler.execute_sql()
  File "/www/web/django_video/env/lib/python2.7/site-packages/django/db/models/sql/compiler.py", line 850, in execute_sql
    cursor = self.connection.cursor()
  File "/www/web/django_video/env/lib/python2.7/site-packages/django/db/backends/base/base.py", line 231, in cursor
    cursor = self.make_debug_cursor(self._cursor())
  File "/www/web/django_video/env/lib/python2.7/site-packages/django/db/backends/base/base.py", line 204, in _cursor
    self.ensure_connection()
  File "/www/web/django_video/env/lib/python2.7/site-packages/django/db/backends/base/base.py", line 199, in ensure_connection
    self.connect()
  File "/www/web/django_video/env/lib/python2.7/site-packages/django/db/utils.py", line 95, in __exit__
    six.reraise(dj_exc_type, dj_exc_value, traceback)
  File "/www/web/django_video/env/lib/python2.7/site-packages/django/db/backends/base/base.py", line 199, in ensure_connection
    self.connect()
  File "/www/web/django_video/env/lib/python2.7/site-packages/django/db/backends/base/base.py", line 171, in connect
    self.connection = self.get_new_connection(conn_params)
  File "/www/web/django_video/env/lib/python2.7/site-packages/django/db/backends/mysql/base.py", line 264, in get_new_connection
    conn = Database.connect(**conn_params)
  File "/www/web/django_video/env/lib/python2.7/site-packages/MySQLdb/__init__.py", line 81, in Connect
    return Connection(*args, **kwargs)
  File "/www/web/django_video/env/lib/python2.7/site-packages/MySQLdb/connections.py", line 193, in __init__
    super(Connection, self).__init__(*args, **kwargs2)
OperationalError: (2002, "Can't connect to local MySQL server through socket '/var/lib/mysql/mysql.sock' (2)")
Internal Server Error: /
Traceback (most recent call last):
  File "/www/web/django_video/env/lib/python2.7/site-packages/django/core/handlers/base.py", line 149, in get_response
    response = self.process_exception_by_middleware(e, request)
  File "/www/web/django_video/env/lib/python2.7/site-packages/django/core/handlers/base.py", line 147, in get_response
    response = wrapped_callback(request, *callback_args, **callback_kwargs)
  File "/www/web/django_video/video_omsa/video/views.py", line 98, in index
    navs = list(Nav.objects.all())
  File "/www/web/django_video/env/lib/python2.7/site-packages/django/db/models/query.py", line 258, in __iter__
    self._fetch_all()
  File "/www/web/django_video/env/lib/python2.7/site-packages/django/db/models/query.py", line 1074, in _fetch_all
    self._result_cache = list(self.iterator())
  File "/www/web/django_video/env/lib/python2.7/site-packages/django/db/models/query.py", line 52, in __iter__
    results = compiler.execute_sql()
  File "/www/web/django_video/env/lib/python2.7/site-packages/django/db/models/sql/compiler.py", line 850, in execute_sql
    cursor = self.connection.cursor()
  File "/www/web/django_video/env/lib/python2.7/site-packages/django/db/backends/base/base.py", line 231, in cursor
    cursor = self.make_debug_cursor(self._cursor())
  File "/www/web/django_video/env/lib/python2.7/site-packages/django/db/backends/base/base.py", line 204, in _cursor
    self.ensure_connection()
  File "/www/web/django_video/env/lib/python2.7/site-packages/django/db/backends/base/base.py", line 199, in ensure_connection
    self.connect()
  File "/www/web/django_video/env/lib/python2.7/site-packages/django/db/utils.py", line 95, in __exit__
    six.reraise(dj_exc_type, dj_exc_value, traceback)
  File "/www/web/django_video/env/lib/python2.7/site-packages/django/db/backends/base/base.py", line 199, in ensure_connection
    self.connect()
  File "/www/web/django_video/env/lib/python2.7/site-packages/django/db/backends/base/base.py", line 171, in connect
    self.connection = self.get_new_connection(conn_params)
  File "/www/web/django_video/env/lib/python2.7/site-packages/django/db/backends/mysql/base.py", line 264, in get_new_connection
    conn = Database.connect(**conn_params)
  File "/www/web/django_video/env/lib/python2.7/site-packages/MySQLdb/__init__.py", line 81, in Connect
    return Connection(*args, **kwargs)
  File "/www/web/django_video/env/lib/python2.7/site-packages/MySQLdb/connections.py", line 193, in __init__
    super(Connection, self).__init__(*args, **kwargs2)
OperationalError: (2002, "Can't connect to local MySQL server through socket '/var/lib/mysql/mysql.sock' (2)")
[05/Jul/2017 21:58:50] "GET / HTTP/1.0" 500 140073
- Broken pipe from ('127.0.0.1', 46556)
Not Found: /http:/www.proxylists.net/proxyjudge.php
Not Found: /http:/www.proxylists.net/proxyjudge.php
[05/Jul/2017 23:40:12] "GET http://www.proxylists.net/proxyjudge.php HTTP/1.1" 404 1722
[05/Jul/2017 23:40:18] code 400, message Bad request syntax ('\x05\x02\x00\x01')
[05/Jul/2017 23:40:18] " " 400 -
[05/Jul/2017 23:40:24] code 400, message Bad request syntax ('\x04\x01\x00P\xc6\xffbK\x00')
[05/Jul/2017 23:40:24] 
Internal Server Error: /
Traceback (most recent call last):
  File "/www/web/django_video/env/lib/python2.7/site-packages/django/core/handlers/base.py", line 149, in get_response
    response = self.process_exception_by_middleware(e, request)
  File "/www/web/django_video/env/lib/python2.7/site-packages/django/core/handlers/base.py", line 147, in get_response
    response = wrapped_callback(request, *callback_args, **callback_kwargs)
  File "/www/web/django_video/video_omsa/video/views.py", line 98, in index
    navs = list(Nav.objects.all())
  File "/www/web/django_video/env/lib/python2.7/site-packages/django/db/models/query.py", line 258, in __iter__
    self._fetch_all()
  File "/www/web/django_video/env/lib/python2.7/site-packages/django/db/models/query.py", line 1074, in _fetch_all
    self._result_cache = list(self.iterator())
  File "/www/web/django_video/env/lib/python2.7/site-packages/django/db/models/query.py", line 52, in __iter__
    results = compiler.execute_sql()
  File "/www/web/django_video/env/lib/python2.7/site-packages/django/db/models/sql/compiler.py", line 850, in execute_sql
    cursor = self.connection.cursor()
  File "/www/web/django_video/env/lib/python2.7/site-packages/django/db/backends/base/base.py", line 231, in cursor
    cursor = self.make_debug_cursor(self._cursor())
  File "/www/web/django_video/env/lib/python2.7/site-packages/django/db/backends/base/base.py", line 204, in _cursor
    self.ensure_connection()
  File "/www/web/django_video/env/lib/python2.7/site-packages/django/db/backends/base/base.py", line 199, in ensure_connection
    self.connect()
  File "/www/web/django_video/env/lib/python2.7/site-packages/django/db/utils.py", line 95, in __exit__
    six.reraise(dj_exc_type, dj_exc_value, traceback)
  File "/www/web/django_video/env/lib/python2.7/site-packages/django/db/backends/base/base.py", line 199, in ensure_connection
    self.connect()
  File "/www/web/django_video/env/lib/python2.7/site-packages/django/db/backends/base/base.py", line 171, in connect
    self.connection = self.get_new_connection(conn_params)
  File "/www/web/django_video/env/lib/python2.7/site-packages/django/db/backends/mysql/base.py", line 264, in get_new_connection
    conn = Database.connect(**conn_params)
  File "/www/web/django_video/env/lib/python2.7/site-packages/MySQLdb/__init__.py", line 81, in Connect
    return Connection(*args, **kwargs)
  File "/www/web/django_video/env/lib/python2.7/site-packages/MySQLdb/connections.py", line 193, in __init__
    super(Connection, self).__init__(*args, **kwargs2)
OperationalError: (2002, "Can't connect to local MySQL server through socket '/var/lib/mysql/mysql.sock' (2)")
Internal Server Error: /
Traceback (most recent call last):
  File "/www/web/django_video/env/lib/python2.7/site-packages/django/core/handlers/base.py", line 149, in get_response
    response = self.process_exception_by_middleware(e, request)
  File "/www/web/django_video/env/lib/python2.7/site-packages/django/core/handlers/base.py", line 147, in get_response
    response = wrapped_callback(request, *callback_args, **callback_kwargs)
  File "/www/web/django_video/video_omsa/video/views.py", line 98, in index
    navs = list(Nav.objects.all())
  File "/www/web/django_video/env/lib/python2.7/site-packages/django/db/models/query.py", line 258, in __iter__
    self._fetch_all()
  File "/www/web/django_video/env/lib/python2.7/site-packages/django/db/models/query.py", line 1074, in _fetch_all
    self._result_cache = list(self.iterator())
  File "/www/web/django_video/env/lib/python2.7/site-packages/django/db/models/query.py", line 52, in __iter__
    results = compiler.execute_sql()
  File "/www/web/django_video/env/lib/python2.7/site-packages/django/db/models/sql/compiler.py", line 850, in execute_sql
    cursor = self.connection.cursor()
  File "/www/web/django_video/env/lib/python2.7/site-packages/django/db/backends/base/base.py", line 231, in cursor
    cursor = self.make_debug_cursor(self._cursor())
  File "/www/web/django_video/env/lib/python2.7/site-packages/django/db/backends/base/base.py", line 204, in _cursor
    self.ensure_connection()
  File "/www/web/django_video/env/lib/python2.7/site-packages/django/db/backends/base/base.py", line 199, in ensure_connection
    self.connect()
  File "/www/web/django_video/env/lib/python2.7/site-packages/django/db/utils.py", line 95, in __exit__
    six.reraise(dj_exc_type, dj_exc_value, traceback)
  File "/www/web/django_video/env/lib/python2.7/site-packages/django/db/backends/base/base.py", line 199, in ensure_connection
    self.connect()
  File "/www/web/django_video/env/lib/python2.7/site-packages/django/db/backends/base/base.py", line 171, in connect
    self.connection = self.get_new_connection(conn_params)
  File "/www/web/django_video/env/lib/python2.7/site-packages/django/db/backends/mysql/base.py", line 264, in get_new_connection
    conn = Database.connect(**conn_params)
  File "/www/web/django_video/env/lib/python2.7/site-packages/MySQLdb/__init__.py", line 81, in Connect
    return Connection(*args, **kwargs)
  File "/www/web/django_video/env/lib/python2.7/site-packages/MySQLdb/connections.py", line 193, in __init__
    super(Connection, self).__init__(*args, **kwargs2)
OperationalError: (2002, "Can't connect to local MySQL server through socket '/var/lib/mysql/mysql.sock' (2)")
[05/Jul/2017 23:48:32] "GET / HTTP/1.1" 500 139785
Internal Server Error: /
Traceback (most recent call last):
  File "/www/web/django_video/env/lib/python2.7/site-packages/django/core/handlers/base.py", line 149, in get_response
    response = self.process_exception_by_middleware(e, request)
  File "/www/web/django_video/env/lib/python2.7/site-packages/django/core/handlers/base.py", line 147, in get_response
    response = wrapped_callback(request, *callback_args, **callback_kwargs)
  File "/www/web/django_video/video_omsa/video/views.py", line 98, in index
    navs = list(Nav.objects.all())
  File "/www/web/django_video/env/lib/python2.7/site-packages/django/db/models/query.py", line 258, in __iter__
    self._fetch_all()
  File "/www/web/django_video/env/lib/python2.7/site-packages/django/db/models/query.py", line 1074, in _fetch_all
    self._result_cache = list(self.iterator())
  File "/www/web/django_video/env/lib/python2.7/site-packages/django/db/models/query.py", line 52, in __iter__
    results = compiler.execute_sql()
  File "/www/web/django_video/env/lib/python2.7/site-packages/django/db/models/sql/compiler.py", line 850, in execute_sql
    cursor = self.connection.cursor()
  File "/www/web/django_video/env/lib/python2.7/site-packages/django/db/backends/base/base.py", line 231, in cursor
    cursor = self.make_debug_cursor(self._cursor())
  File "/www/web/django_video/env/lib/python2.7/site-packages/django/db/backends/base/base.py", line 204, in _cursor
    self.ensure_connection()
  File "/www/web/django_video/env/lib/python2.7/site-packages/django/db/backends/base/base.py", line 199, in ensure_connection
    self.connect()
  File "/www/web/django_video/env/lib/python2.7/site-packages/django/db/utils.py", line 95, in __exit__
    six.reraise(dj_exc_type, dj_exc_value, traceback)
  File "/www/web/django_video/env/lib/python2.7/site-packages/django/db/backends/base/base.py", line 199, in ensure_connection
    self.connect()
  File "/www/web/django_video/env/lib/python2.7/site-packages/django/db/backends/base/base.py", line 171, in connect
    self.connection = self.get_new_connection(conn_params)
  File "/www/web/django_video/env/lib/python2.7/site-packages/django/db/backends/mysql/base.py", line 264, in get_new_connection
    conn = Database.connect(**conn_params)
  File "/www/web/django_video/env/lib/python2.7/site-packages/MySQLdb/__init__.py", line 81, in Connect
    return Connection(*args, **kwargs)
  File "/www/web/django_video/env/lib/python2.7/site-packages/MySQLdb/connections.py", line 193, in __init__
    super(Connection, self).__init__(*args, **kwargs2)
OperationalError: (2002, "Can't connect to local MySQL server through socket '/var/lib/mysql/mysql.sock' (2)")
Internal Server Error: /
Traceback (most recent call last):
  File "/www/web/django_video/env/lib/python2.7/site-packages/django/core/handlers/base.py", line 149, in get_response
    response = self.process_exception_by_middleware(e, request)
  File "/www/web/django_video/env/lib/python2.7/site-packages/django/core/handlers/base.py", line 147, in get_response
    response = wrapped_callback(request, *callback_args, **callback_kwargs)
  File "/www/web/django_video/video_omsa/video/views.py", line 98, in index
    navs = list(Nav.objects.all())
  File "/www/web/django_video/env/lib/python2.7/site-packages/django/db/models/query.py", line 258, in __iter__
    self._fetch_all()
  File "/www/web/django_video/env/lib/python2.7/site-packages/django/db/models/query.py", line 1074, in _fetch_all
    self._result_cache = list(self.iterator())
  File "/www/web/django_video/env/lib/python2.7/site-packages/django/db/models/query.py", line 52, in __iter__
    results = compiler.execute_sql()
  File "/www/web/django_video/env/lib/python2.7/site-packages/django/db/models/sql/compiler.py", line 850, in execute_sql
    cursor = self.connection.cursor()
  File "/www/web/django_video/env/lib/python2.7/site-packages/django/db/backends/base/base.py", line 231, in cursor
    cursor = self.make_debug_cursor(self._cursor())
  File "/www/web/django_video/env/lib/python2.7/site-packages/django/db/backends/base/base.py", line 204, in _cursor
    self.ensure_connection()
  File "/www/web/django_video/env/lib/python2.7/site-packages/django/db/backends/base/base.py", line 199, in ensure_connection
    self.connect()
  File "/www/web/django_video/env/lib/python2.7/site-packages/django/db/utils.py", line 95, in __exit__
    six.reraise(dj_exc_type, dj_exc_value, traceback)
  File "/www/web/django_video/env/lib/python2.7/site-packages/django/db/backends/base/base.py", line 199, in ensure_connection
    self.connect()
  File "/www/web/django_video/env/lib/python2.7/site-packages/django/db/backends/base/base.py", line 171, in connect
    self.connection = self.get_new_connection(conn_params)
  File "/www/web/django_video/env/lib/python2.7/site-packages/django/db/backends/mysql/base.py", line 264, in get_new_connection
    conn = Database.connect(**conn_params)
  File "/www/web/django_video/env/lib/python2.7/site-packages/MySQLdb/__init__.py", line 81, in Connect
    return Connection(*args, **kwargs)
  File "/www/web/django_video/env/lib/python2.7/site-packages/MySQLdb/connections.py", line 193, in __init__
    super(Connection, self).__init__(*args, **kwargs2)
OperationalError: (2002, "Can't connect to local MySQL server through socket '/var/lib/mysql/mysql.sock' (2)")
[06/Jul/2017 00:12:03] "GET / HTTP/1.0" 500 139629
Internal Server Error: /
Traceback (most recent call last):
  File "/www/web/django_video/env/lib/python2.7/site-packages/django/core/handlers/base.py", line 149, in get_response
    response = self.process_exception_by_middleware(e, request)
  File "/www/web/django_video/env/lib/python2.7/site-packages/django/core/handlers/base.py", line 147, in get_response
    response = wrapped_callback(request, *callback_args, **callback_kwargs)
  File "/www/web/django_video/video_omsa/video/views.py", line 98, in index
    navs = list(Nav.objects.all())
  File "/www/web/django_video/env/lib/python2.7/site-packages/django/db/models/query.py", line 258, in __iter__
    self._fetch_all()
  File "/www/web/django_video/env/lib/python2.7/site-packages/django/db/models/query.py", line 1074, in _fetch_all
    self._result_cache = list(self.iterator())
  File "/www/web/django_video/env/lib/python2.7/site-packages/django/db/models/query.py", line 52, in __iter__
    results = compiler.execute_sql()
  File "/www/web/django_video/env/lib/python2.7/site-packages/django/db/models/sql/compiler.py", line 850, in execute_sql
    cursor = self.connection.cursor()
  File "/www/web/django_video/env/lib/python2.7/site-packages/django/db/backends/base/base.py", line 231, in cursor
    cursor = self.make_debug_cursor(self._cursor())
  File "/www/web/django_video/env/lib/python2.7/site-packages/django/db/backends/base/base.py", line 204, in _cursor
    self.ensure_connection()
  File "/www/web/django_video/env/lib/python2.7/site-packages/django/db/backends/base/base.py", line 199, in ensure_connection
    self.connect()
  File "/www/web/django_video/env/lib/python2.7/site-packages/django/db/utils.py", line 95, in __exit__
    six.reraise(dj_exc_type, dj_exc_value, traceback)
  File "/www/web/django_video/env/lib/python2.7/site-packages/django/db/backends/base/base.py", line 199, in ensure_connection
    self.connect()
  File "/www/web/django_video/env/lib/python2.7/site-packages/django/db/backends/base/base.py", line 171, in connect
    self.connection = self.get_new_connection(conn_params)
  File "/www/web/django_video/env/lib/python2.7/site-packages/django/db/backends/mysql/base.py", line 264, in get_new_connection
    conn = Database.connect(**conn_params)
  File "/www/web/django_video/env/lib/python2.7/site-packages/MySQLdb/__init__.py", line 81, in Connect
    return Connection(*args, **kwargs)
  File "/www/web/django_video/env/lib/python2.7/site-packages/MySQLdb/connections.py", line 193, in __init__
    super(Connection, self).__init__(*args, **kwargs2)
OperationalError: (2002, "Can't connect to local MySQL server through socket '/var/lib/mysql/mysql.sock' (2)")
Internal Server Error: /
Traceback (most recent call last):
  File "/www/web/django_video/env/lib/python2.7/site-packages/django/core/handlers/base.py", line 149, in get_response
    response = self.process_exception_by_middleware(e, request)
  File "/www/web/django_video/env/lib/python2.7/site-packages/django/core/handlers/base.py", line 147, in get_response
    response = wrapped_callback(request, *callback_args, **callback_kwargs)
  File "/www/web/django_video/video_omsa/video/views.py", line 98, in index
    navs = list(Nav.objects.all())
  File "/www/web/django_video/env/lib/python2.7/site-packages/django/db/models/query.py", line 258, in __iter__
    self._fetch_all()
  File "/www/web/django_video/env/lib/python2.7/site-packages/django/db/models/query.py", line 1074, in _fetch_all
    self._result_cache = list(self.iterator())
  File "/www/web/django_video/env/lib/python2.7/site-packages/django/db/models/query.py", line 52, in __iter__
    results = compiler.execute_sql()
  File "/www/web/django_video/env/lib/python2.7/site-packages/django/db/models/sql/compiler.py", line 850, in execute_sql
    cursor = self.connection.cursor()
  File "/www/web/django_video/env/lib/python2.7/site-packages/django/db/backends/base/base.py", line 231, in cursor
    cursor = self.make_debug_cursor(self._cursor())
  File "/www/web/django_video/env/lib/python2.7/site-packages/django/db/backends/base/base.py", line 204, in _cursor
    self.ensure_connection()
  File "/www/web/django_video/env/lib/python2.7/site-packages/django/db/backends/base/base.py", line 199, in ensure_connection
    self.connect()
  File "/www/web/django_video/env/lib/python2.7/site-packages/django/db/utils.py", line 95, in __exit__
    six.reraise(dj_exc_type, dj_exc_value, traceback)
  File "/www/web/django_video/env/lib/python2.7/site-packages/django/db/backends/base/base.py", line 199, in ensure_connection
    self.connect()
  File "/www/web/django_video/env/lib/python2.7/site-packages/django/db/backends/base/base.py", line 171, in connect
    self.connection = self.get_new_connection(conn_params)
  File "/www/web/django_video/env/lib/python2.7/site-packages/django/db/backends/mysql/base.py", line 264, in get_new_connection
    conn = Database.connect(**conn_params)
  File "/www/web/django_video/env/lib/python2.7/site-packages/MySQLdb/__init__.py", line 81, in Connect
    return Connection(*args, **kwargs)
  File "/www/web/django_video/env/lib/python2.7/site-packages/MySQLdb/connections.py", line 193, in __init__
    super(Connection, self).__init__(*args, **kwargs2)
OperationalError: (2002, "Can't connect to local MySQL server through socket '/var/lib/mysql/mysql.sock' (2)")
[06/Jul/2017 06:20:28] "GET / HTTP/1.0" 500 139635
Internal Server Error: /
Traceback (most recent call last):
  File "/www/web/django_video/env/lib/python2.7/site-packages/django/core/handlers/base.py", line 149, in get_response
    response = self.process_exception_by_middleware(e, request)
  File "/www/web/django_video/env/lib/python2.7/site-packages/django/core/handlers/base.py", line 147, in get_response
    response = wrapped_callback(request, *callback_args, **callback_kwargs)
  File "/www/web/django_video/video_omsa/video/views.py", line 98, in index
    navs = list(Nav.objects.all())
  File "/www/web/django_video/env/lib/python2.7/site-packages/django/db/models/query.py", line 258, in __iter__
    self._fetch_all()
  File "/www/web/django_video/env/lib/python2.7/site-packages/django/db/models/query.py", line 1074, in _fetch_all
    self._result_cache = list(self.iterator())
  File "/www/web/django_video/env/lib/python2.7/site-packages/django/db/models/query.py", line 52, in __iter__
    results = compiler.execute_sql()
  File "/www/web/django_video/env/lib/python2.7/site-packages/django/db/models/sql/compiler.py", line 850, in execute_sql
    cursor = self.connection.cursor()
  File "/www/web/django_video/env/lib/python2.7/site-packages/django/db/backends/base/base.py", line 231, in cursor
    cursor = self.make_debug_cursor(self._cursor())
  File "/www/web/django_video/env/lib/python2.7/site-packages/django/db/backends/base/base.py", line 204, in _cursor
    self.ensure_connection()
  File "/www/web/django_video/env/lib/python2.7/site-packages/django/db/backends/base/base.py", line 199, in ensure_connection
    self.connect()
  File "/www/web/django_video/env/lib/python2.7/site-packages/django/db/utils.py", line 95, in __exit__
    six.reraise(dj_exc_type, dj_exc_value, traceback)
  File "/www/web/django_video/env/lib/python2.7/site-packages/django/db/backends/base/base.py", line 199, in ensure_connection
    self.connect()
  File "/www/web/django_video/env/lib/python2.7/site-packages/django/db/backends/base/base.py", line 171, in connect
    self.connection = self.get_new_connection(conn_params)
  File "/www/web/django_video/env/lib/python2.7/site-packages/django/db/backends/mysql/base.py", line 264, in get_new_connection
    conn = Database.connect(**conn_params)
  File "/www/web/django_video/env/lib/python2.7/site-packages/MySQLdb/__init__.py", line 81, in Connect
    return Connection(*args, **kwargs)
  File "/www/web/django_video/env/lib/python2.7/site-packages/MySQLdb/connections.py", line 193, in __init__
    super(Connection, self).__init__(*args, **kwargs2)
OperationalError: (2002, "Can't connect to local MySQL server through socket '/var/lib/mysql/mysql.sock' (2)")
Internal Server Error: /
Traceback (most recent call last):
  File "/www/web/django_video/env/lib/python2.7/site-packages/django/core/handlers/base.py", line 149, in get_response
    response = self.process_exception_by_middleware(e, request)
  File "/www/web/django_video/env/lib/python2.7/site-packages/django/core/handlers/base.py", line 147, in get_response
    response = wrapped_callback(request, *callback_args, **callback_kwargs)
  File "/www/web/django_video/video_omsa/video/views.py", line 98, in index
    navs = list(Nav.objects.all())
  File "/www/web/django_video/env/lib/python2.7/site-packages/django/db/models/query.py", line 258, in __iter__
    self._fetch_all()
  File "/www/web/django_video/env/lib/python2.7/site-packages/django/db/models/query.py", line 1074, in _fetch_all
    self._result_cache = list(self.iterator())
  File "/www/web/django_video/env/lib/python2.7/site-packages/django/db/models/query.py", line 52, in __iter__
    results = compiler.execute_sql()
  File "/www/web/django_video/env/lib/python2.7/site-packages/django/db/models/sql/compiler.py", line 850, in execute_sql
    cursor = self.connection.cursor()
  File "/www/web/django_video/env/lib/python2.7/site-packages/django/db/backends/base/base.py", line 231, in cursor
    cursor = self.make_debug_cursor(self._cursor())
  File "/www/web/django_video/env/lib/python2.7/site-packages/django/db/backends/base/base.py", line 204, in _cursor
    self.ensure_connection()
  File "/www/web/django_video/env/lib/python2.7/site-packages/django/db/backends/base/base.py", line 199, in ensure_connection
    self.connect()
  File "/www/web/django_video/env/lib/python2.7/site-packages/django/db/utils.py", line 95, in __exit__
    six.reraise(dj_exc_type, dj_exc_value, traceback)
  File "/www/web/django_video/env/lib/python2.7/site-packages/django/db/backends/base/base.py", line 199, in ensure_connection
    self.connect()
  File "/www/web/django_video/env/lib/python2.7/site-packages/django/db/backends/base/base.py", line 171, in connect
    self.connection = self.get_new_connection(conn_params)
  File "/www/web/django_video/env/lib/python2.7/site-packages/django/db/backends/mysql/base.py", line 264, in get_new_connection
    conn = Database.connect(**conn_params)
  File "/www/web/django_video/env/lib/python2.7/site-packages/MySQLdb/__init__.py", line 81, in Connect
    return Connection(*args, **kwargs)
  File "/www/web/django_video/env/lib/python2.7/site-packages/MySQLdb/connections.py", line 193, in __init__
    super(Connection, self).__init__(*args, **kwargs2)
OperationalError: (2002, "Can't connect to local MySQL server through socket '/var/lib/mysql/mysql.sock' (2)")
[06/Jul/2017 09:11:13] "GET / HTTP/1.0" 500 140213
Internal Server Error: /im_list.html
Traceback (most recent call last):
  File "/www/web/django_video/env/lib/python2.7/site-packages/django/core/handlers/base.py", line 149, in get_response
    response = self.process_exception_by_middleware(e, request)
  File "/www/web/django_video/env/lib/python2.7/site-packages/django/core/handlers/base.py", line 147, in get_response
    response = wrapped_callback(request, *callback_args, **callback_kwargs)
  File "/www/web/django_video/video_omsa/video/views.py", line 106, in imList
    navs = list(Nav.objects.all())
  File "/www/web/django_video/env/lib/python2.7/site-packages/django/db/models/query.py", line 258, in __iter__
    self._fetch_all()
  File "/www/web/django_video/env/lib/python2.7/site-packages/django/db/models/query.py", line 1074, in _fetch_all
    self._result_cache = list(self.iterator())
  File "/www/web/django_video/env/lib/python2.7/site-packages/django/db/models/query.py", line 52, in __iter__
    results = compiler.execute_sql()
  File "/www/web/django_video/env/lib/python2.7/site-packages/django/db/models/sql/compiler.py", line 850, in execute_sql
    cursor = self.connection.cursor()
  File "/www/web/django_video/env/lib/python2.7/site-packages/django/db/backends/base/base.py", line 231, in cursor
    cursor = self.make_debug_cursor(self._cursor())
  File "/www/web/django_video/env/lib/python2.7/site-packages/django/db/backends/base/base.py", line 204, in _cursor
    self.ensure_connection()
  File "/www/web/django_video/env/lib/python2.7/site-packages/django/db/backends/base/base.py", line 199, in ensure_connection
    self.connect()
  File "/www/web/django_video/env/lib/python2.7/site-packages/django/db/utils.py", line 95, in __exit__
    six.reraise(dj_exc_type, dj_exc_value, traceback)
  File "/www/web/django_video/env/lib/python2.7/site-packages/django/db/backends/base/base.py", line 199, in ensure_connection
    self.connect()
  File "/www/web/django_video/env/lib/python2.7/site-packages/django/db/backends/base/base.py", line 171, in connect
    self.connection = self.get_new_connection(conn_params)
  File "/www/web/django_video/env/lib/python2.7/site-packages/django/db/backends/mysql/base.py", line 264, in get_new_connection
    conn = Database.connect(**conn_params)
  File "/www/web/django_video/env/lib/python2.7/site-packages/MySQLdb/__init__.py", line 81, in Connect
    return Connection(*args, **kwargs)
  File "/www/web/django_video/env/lib/python2.7/site-packages/MySQLdb/connections.py", line 193, in __init__
    super(Connection, self).__init__(*args, **kwargs2)
OperationalError: (2002, "Can't connect to local MySQL server through socket '/var/lib/mysql/mysql.sock' (2)")
Internal Server Error: /im_list.html
Traceback (most recent call last):
  File "/www/web/django_video/env/lib/python2.7/site-packages/django/core/handlers/base.py", line 149, in get_response
    response = self.process_exception_by_middleware(e, request)
  File "/www/web/django_video/env/lib/python2.7/site-packages/django/core/handlers/base.py", line 147, in get_response
    response = wrapped_callback(request, *callback_args, **callback_kwargs)
  File "/www/web/django_video/video_omsa/video/views.py", line 106, in imList
    navs = list(Nav.objects.all())
  File "/www/web/django_video/env/lib/python2.7/site-packages/django/db/models/query.py", line 258, in __iter__
    self._fetch_all()
  File "/www/web/django_video/env/lib/python2.7/site-packages/django/db/models/query.py", line 1074, in _fetch_all
    self._result_cache = list(self.iterator())
  File "/www/web/django_video/env/lib/python2.7/site-packages/django/db/models/query.py", line 52, in __iter__
    results = compiler.execute_sql()
  File "/www/web/django_video/env/lib/python2.7/site-packages/django/db/models/sql/compiler.py", line 850, in execute_sql
    cursor = self.connection.cursor()
  File "/www/web/django_video/env/lib/python2.7/site-packages/django/db/backends/base/base.py", line 231, in cursor
    cursor = self.make_debug_cursor(self._cursor())
  File "/www/web/django_video/env/lib/python2.7/site-packages/django/db/backends/base/base.py", line 204, in _cursor
    self.ensure_connection()
  File "/www/web/django_video/env/lib/python2.7/site-packages/django/db/backends/base/base.py", line 199, in ensure_connection
    self.connect()
  File "/www/web/django_video/env/lib/python2.7/site-packages/django/db/utils.py", line 95, in __exit__
    six.reraise(dj_exc_type, dj_exc_value, traceback)
  File "/www/web/django_video/env/lib/python2.7/site-packages/django/db/backends/base/base.py", line 199, in ensure_connection
    self.connect()
  File "/www/web/django_video/env/lib/python2.7/site-packages/django/db/backends/base/base.py", line 171, in connect
    self.connection = self.get_new_connection(conn_params)
  File "/www/web/django_video/env/lib/python2.7/site-packages/django/db/backends/mysql/base.py", line 264, in get_new_connection
    conn = Database.connect(**conn_params)
  File "/www/web/django_video/env/lib/python2.7/site-packages/MySQLdb/__init__.py", line 81, in Connect
    return Connection(*args, **kwargs)
  File "/www/web/django_video/env/lib/python2.7/site-packages/MySQLdb/connections.py", line 193, in __init__
    super(Connection, self).__init__(*args, **kwargs2)
OperationalError: (2002, "Can't connect to local MySQL server through socket '/var/lib/mysql/mysql.sock' (2)")
[06/Jul/2017 10:11:10] "GET /im_list.html HTTP/1.0" 500 141331
Internal Server Error: /im_list.html
Traceback (most recent call last):
  File "/www/web/django_video/env/lib/python2.7/site-packages/django/core/handlers/base.py", line 149, in get_response
    response = self.process_exception_by_middleware(e, request)
  File "/www/web/django_video/env/lib/python2.7/site-packages/django/core/handlers/base.py", line 147, in get_response
    response = wrapped_callback(request, *callback_args, **callback_kwargs)
  File "/www/web/django_video/video_omsa/video/views.py", line 106, in imList
    navs = list(Nav.objects.all())
  File "/www/web/django_video/env/lib/python2.7/site-packages/django/db/models/query.py", line 258, in __iter__
    self._fetch_all()
  File "/www/web/django_video/env/lib/python2.7/site-packages/django/db/models/query.py", line 1074, in _fetch_all
    self._result_cache = list(self.iterator())
  File "/www/web/django_video/env/lib/python2.7/site-packages/django/db/models/query.py", line 52, in __iter__
    results = compiler.execute_sql()
  File "/www/web/django_video/env/lib/python2.7/site-packages/django/db/models/sql/compiler.py", line 850, in execute_sql
    cursor = self.connection.cursor()
  File "/www/web/django_video/env/lib/python2.7/site-packages/django/db/backends/base/base.py", line 231, in cursor
    cursor = self.make_debug_cursor(self._cursor())
  File "/www/web/django_video/env/lib/python2.7/site-packages/django/db/backends/base/base.py", line 204, in _cursor
    self.ensure_connection()
  File "/www/web/django_video/env/lib/python2.7/site-packages/django/db/backends/base/base.py", line 199, in ensure_connection
    self.connect()
  File "/www/web/django_video/env/lib/python2.7/site-packages/django/db/utils.py", line 95, in __exit__
    six.reraise(dj_exc_type, dj_exc_value, traceback)
  File "/www/web/django_video/env/lib/python2.7/site-packages/django/db/backends/base/base.py", line 199, in ensure_connection
    self.connect()
  File "/www/web/django_video/env/lib/python2.7/site-packages/django/db/backends/base/base.py", line 171, in connect
    self.connection = self.get_new_connection(conn_params)
  File "/www/web/django_video/env/lib/python2.7/site-packages/django/db/backends/mysql/base.py", line 264, in get_new_connection
    conn = Database.connect(**conn_params)
  File "/www/web/django_video/env/lib/python2.7/site-packages/MySQLdb/__init__.py", line 81, in Connect
    return Connection(*args, **kwargs)
  File "/www/web/django_video/env/lib/python2.7/site-packages/MySQLdb/connections.py", line 193, in __init__
    super(Connection, self).__init__(*args, **kwargs2)
OperationalError: (2002, "Can't connect to local MySQL server through socket '/var/lib/mysql/mysql.sock' (2)")
Internal Server Error: /im_list.html
Traceback (most recent call last):
  File "/www/web/django_video/env/lib/python2.7/site-packages/django/core/handlers/base.py", line 149, in get_response
    response = self.process_exception_by_middleware(e, request)
  File "/www/web/django_video/env/lib/python2.7/site-packages/django/core/handlers/base.py", line 147, in get_response
    response = wrapped_callback(request, *callback_args, **callback_kwargs)
  File "/www/web/django_video/video_omsa/video/views.py", line 106, in imList
    navs = list(Nav.objects.all())
  File "/www/web/django_video/env/lib/python2.7/site-packages/django/db/models/query.py", line 258, in __iter__
    self._fetch_all()
  File "/www/web/django_video/env/lib/python2.7/site-packages/django/db/models/query.py", line 1074, in _fetch_all
    self._result_cache = list(self.iterator())
  File "/www/web/django_video/env/lib/python2.7/site-packages/django/db/models/query.py", line 52, in __iter__
    results = compiler.execute_sql()
  File "/www/web/django_video/env/lib/python2.7/site-packages/django/db/models/sql/compiler.py", line 850, in execute_sql
    cursor = self.connection.cursor()
  File "/www/web/django_video/env/lib/python2.7/site-packages/django/db/backends/base/base.py", line 231, in cursor
    cursor = self.make_debug_cursor(self._cursor())
  File "/www/web/django_video/env/lib/python2.7/site-packages/django/db/backends/base/base.py", line 204, in _cursor
    self.ensure_connection()
  File "/www/web/django_video/env/lib/python2.7/site-packages/django/db/backends/base/base.py", line 199, in ensure_connection
    self.connect()
  File "/www/web/django_video/env/lib/python2.7/site-packages/django/db/utils.py", line 95, in __exit__
    six.reraise(dj_exc_type, dj_exc_value, traceback)
  File "/www/web/django_video/env/lib/python2.7/site-packages/django/db/backends/base/base.py", line 199, in ensure_connection
    self.connect()
  File "/www/web/django_video/env/lib/python2.7/site-packages/django/db/backends/base/base.py", line 171, in connect
    self.connection = self.get_new_connection(conn_params)
  File "/www/web/django_video/env/lib/python2.7/site-packages/django/db/backends/mysql/base.py", line 264, in get_new_connection
    conn = Database.connect(**conn_params)
  File "/www/web/django_video/env/lib/python2.7/site-packages/MySQLdb/__init__.py", line 81, in Connect
    return Connection(*args, **kwargs)
  File "/www/web/django_video/env/lib/python2.7/site-packages/MySQLdb/connections.py", line 193, in __init__
    super(Connection, self).__init__(*args, **kwargs2)
OperationalError: (2002, "Can't connect to local MySQL server through socket '/var/lib/mysql/mysql.sock' (2)")
[06/Jul/2017 10:11:37] "GET /im_list.html HTTP/1.0" 500 141466
Internal Server Error: /im_list.html
Traceback (most recent call last):
  File "/www/web/django_video/env/lib/python2.7/site-packages/django/core/handlers/base.py", line 149, in get_response
    response = self.process_exception_by_middleware(e, request)
  File "/www/web/django_video/env/lib/python2.7/site-packages/django/core/handlers/base.py", line 147, in get_response
    response = wrapped_callback(request, *callback_args, **callback_kwargs)
  File "/www/web/django_video/video_omsa/video/views.py", line 106, in imList
    navs = list(Nav.objects.all())
  File "/www/web/django_video/env/lib/python2.7/site-packages/django/db/models/query.py", line 258, in __iter__
    self._fetch_all()
  File "/www/web/django_video/env/lib/python2.7/site-packages/django/db/models/query.py", line 1074, in _fetch_all
    self._result_cache = list(self.iterator())
  File "/www/web/django_video/env/lib/python2.7/site-packages/django/db/models/query.py", line 52, in __iter__
    results = compiler.execute_sql()
  File "/www/web/django_video/env/lib/python2.7/site-packages/django/db/models/sql/compiler.py", line 850, in execute_sql
    cursor = self.connection.cursor()
  File "/www/web/django_video/env/lib/python2.7/site-packages/django/db/backends/base/base.py", line 231, in cursor
    cursor = self.make_debug_cursor(self._cursor())
  File "/www/web/django_video/env/lib/python2.7/site-packages/django/db/backends/base/base.py", line 204, in _cursor
    self.ensure_connection()
  File "/www/web/django_video/env/lib/python2.7/site-packages/django/db/backends/base/base.py", line 199, in ensure_connection
    self.connect()
  File "/www/web/django_video/env/lib/python2.7/site-packages/django/db/utils.py", line 95, in __exit__
    six.reraise(dj_exc_type, dj_exc_value, traceback)
  File "/www/web/django_video/env/lib/python2.7/site-packages/django/db/backends/base/base.py", line 199, in ensure_connection
    self.connect()
  File "/www/web/django_video/env/lib/python2.7/site-packages/django/db/backends/base/base.py", line 171, in connect
    self.connection = self.get_new_connection(conn_params)
  File "/www/web/django_video/env/lib/python2.7/site-packages/django/db/backends/mysql/base.py", line 264, in get_new_connection
    conn = Database.connect(**conn_params)
  File "/www/web/django_video/env/lib/python2.7/site-packages/MySQLdb/__init__.py", line 81, in Connect
    return Connection(*args, **kwargs)
  File "/www/web/django_video/env/lib/python2.7/site-packages/MySQLdb/connections.py", line 193, in __init__
    super(Connection, self).__init__(*args, **kwargs2)
OperationalError: (2002, "Can't connect to local MySQL server through socket '/var/lib/mysql/mysql.sock' (2)")
Internal Server Error: /im_list.html
Traceback (most recent call last):
  File "/www/web/django_video/env/lib/python2.7/site-packages/django/core/handlers/base.py", line 149, in get_response
    response = self.process_exception_by_middleware(e, request)
  File "/www/web/django_video/env/lib/python2.7/site-packages/django/core/handlers/base.py", line 147, in get_response
    response = wrapped_callback(request, *callback_args, **callback_kwargs)
  File "/www/web/django_video/video_omsa/video/views.py", line 106, in imList
    navs = list(Nav.objects.all())
  File "/www/web/django_video/env/lib/python2.7/site-packages/django/db/models/query.py", line 258, in __iter__
    self._fetch_all()
  File "/www/web/django_video/env/lib/python2.7/site-packages/django/db/models/query.py", line 1074, in _fetch_all
    self._result_cache = list(self.iterator())
  File "/www/web/django_video/env/lib/python2.7/site-packages/django/db/models/query.py", line 52, in __iter__
    results = compiler.execute_sql()
  File "/www/web/django_video/env/lib/python2.7/site-packages/django/db/models/sql/compiler.py", line 850, in execute_sql
    cursor = self.connection.cursor()
  File "/www/web/django_video/env/lib/python2.7/site-packages/django/db/backends/base/base.py", line 231, in cursor
    cursor = self.make_debug_cursor(self._cursor())
  File "/www/web/django_video/env/lib/python2.7/site-packages/django/db/backends/base/base.py", line 204, in _cursor
    self.ensure_connection()
  File "/www/web/django_video/env/lib/python2.7/site-packages/django/db/backends/base/base.py", line 199, in ensure_connection
    self.connect()
  File "/www/web/django_video/env/lib/python2.7/site-packages/django/db/utils.py", line 95, in __exit__
    six.reraise(dj_exc_type, dj_exc_value, traceback)
  File "/www/web/django_video/env/lib/python2.7/site-packages/django/db/backends/base/base.py", line 199, in ensure_connection
    self.connect()
  File "/www/web/django_video/env/lib/python2.7/site-packages/django/db/backends/base/base.py", line 171, in connect
    self.connection = self.get_new_connection(conn_params)
  File "/www/web/django_video/env/lib/python2.7/site-packages/django/db/backends/mysql/base.py", line 264, in get_new_connection
    conn = Database.connect(**conn_params)
  File "/www/web/django_video/env/lib/python2.7/site-packages/MySQLdb/__init__.py", line 81, in Connect
    return Connection(*args, **kwargs)
  File "/www/web/django_video/env/lib/python2.7/site-packages/MySQLdb/connections.py", line 193, in __init__
    super(Connection, self).__init__(*args, **kwargs2)
OperationalError: (2002, "Can't connect to local MySQL server through socket '/var/lib/mysql/mysql.sock' (2)")
[06/Jul/2017 10:11:41] "GET /im_list.html HTTP/1.0" 500 141466
[06/Jul/2017 10:13:26] "GET /im_list.html HTTP/1.0" 200 5970
[06/Jul/2017 10:13:27] "GET / HTTP/1.0" 200 6894
[06/Jul/2017 10:13:29] "POST /login HTTP/1.0" 302 0
[06/Jul/2017 10:13:29] "GET /im_list.html HTTP/1.0" 200 5826
Not Found: /xiyizhiyeyishi/progress
Not Found: /xiyizhiyeyishi/progress
[06/Jul/2017 10:13:34] "GET /xiyizhiyeyishi/progress HTTP/1.0" 404 3864
[06/Jul/2017 10:13:45] "GET /inters_data HTTP/1.0" 200 6884
[06/Jul/2017 10:13:47] "GET /im_list.html HTTP/1.0" 200 5826
[06/Jul/2017 10:13:49] "GET /add HTTP/1.0" 200 2455
[06/Jul/2017 10:13:52] "GET /upload HTTP/1.0" 200 1919
[06/Jul/2017 10:14:12] "GET /addIm HTTP/1.0" 200 5800
[06/Jul/2017 10:14:18] "GET /im_list.html HTTP/1.0" 200 5826
[06/Jul/2017 10:15:13] "GET /upload HTTP/1.0" 200 1919
Internal Server Error: /up_recive
Traceback (most recent call last):
  File "/www/web/django_video/env/lib/python2.7/site-packages/django/core/handlers/base.py", line 149, in get_response
    response = self.process_exception_by_middleware(e, request)
  File "/www/web/django_video/env/lib/python2.7/site-packages/django/core/handlers/base.py", line 147, in get_response
    response = wrapped_callback(request, *callback_args, **callback_kwargs)
  File "/www/web/django_video/video_omsa/video/views.py", line 157, in up_recive
    save_destination = open(os.path.join("uploads",files.name),'wb+') # 打开特定的文件进行二进制写操作
NameError: global name 'os' is not defined
Internal Server Error: /up_recive
Traceback (most recent call last):
  File "/www/web/django_video/env/lib/python2.7/site-packages/django/core/handlers/base.py", line 149, in get_response
    response = self.process_exception_by_middleware(e, request)
  File "/www/web/django_video/env/lib/python2.7/site-packages/django/core/handlers/base.py", line 147, in get_response
    response = wrapped_callback(request, *callback_args, **callback_kwargs)
  File "/www/web/django_video/video_omsa/video/views.py", line 157, in up_recive
    save_destination = open(os.path.join("uploads",files.name),'wb+') # 打开特定的文件进行二进制写操作
NameError: global name 'os' is not defined
[06/Jul/2017 10:15:24] "POST /up_recive HTTP/1.0" 500 67586
Performing system checks...

System check identified no issues (0 silenced).
July 05, 2017 - 18:05:34
Django version 1.9, using settings 'video_omsa.settings'
Starting development server at http://0.0.0.0:88/
Quit the server with CONTROL-C.
(1064, "You have an error in your SQL syntax; check the manual that corresponds to your MySQL server version for the right syntax to use near 'desclimit 23' at line 1")
(1064, "You have an error in your SQL syntax; check the manual that corresponds to your MySQL server version for the right syntax to use near 'desclimit 23' at line 1")
(1064, "You have an error in your SQL syntax; check the manual that corresponds to your MySQL server version for the right syntax to use near 'desclimit 23' at line 1")
(1064, "You have an error in your SQL syntax; check the manual that corresponds to your MySQL server version for the right syntax to use near 'desclimit 23' at line 1")
(1064, "You have an error in your SQL syntax; check the manual that corresponds to your MySQL server version for the right syntax to use near 'desclimit 23' at line 1")
(1064, "You have an error in your SQL syntax; check the manual that corresponds to your MySQL server version for the right syntax to use near 'desclimit 23' at line 1")
(1064, "You have an error in your SQL syntax; check the manual that corresponds to your MySQL server version for the right syntax to use near 'desclimit 23' at line 1")
(1064, "You have an error in your SQL syntax; check the manual that corresponds to your MySQL server version for the right syntax to use near 'desclimit 23' at line 1")
(1064, "You have an error in your SQL syntax; check the manual that corresponds to your MySQL server version for the right syntax to use near 'desclimit 23' at line 1")
(1064, "You have an error in your SQL syntax; check the manual that corresponds to your MySQL server version for the right syntax to use near 'desclimit 23' at line 1")
(1064, "You have an error in your SQL syntax; check the manual that corresponds to your MySQL server version for the right syntax to use near 'desclimit 23' at line 1")
(1064, "You have an error in your SQL syntax; check the manual that corresponds to your MySQL server version for the right syntax to use near 'desclimit 23' at line 1")
(1064, "You have an error in your SQL syntax; check the manual that corresponds to your MySQL server version for the right syntax to use near 'desclimit 23' at line 1")
(1064, "You have an error in your SQL syntax; check the manual that corresponds to your MySQL server version for the right syntax to use near 'desclimit 23' at line 1")
(1064, "You have an error in your SQL syntax; check the manual that corresponds to your MySQL server version for the right syntax to use near 'desclimit 23' at line 1")
(1064, "You have an error in your SQL syntax; check the manual that corresponds to your MySQL server version for the right syntax to use near 'desclimit 23' at line 1")
(1064, "You have an error in your SQL syntax; check the manual that corresponds to your MySQL server version for the right syntax to use near 'desclimit 23' at line 1")
(1064, "You have an error in your SQL syntax; check the manual that corresponds to your MySQL server version for the right syntax to use near 'desclimit 23' at line 1")
Internal Server Error: /up_recive
Traceback (most recent call last):
  File "/www/web/django_video/env/lib/python2.7/site-packages/django/core/handlers/base.py", line 149, in get_response
    response = self.process_exception_by_middleware(e, request)
  File "/www/web/django_video/env/lib/python2.7/site-packages/django/core/handlers/base.py", line 147, in get_response
    response = wrapped_callback(request, *callback_args, **callback_kwargs)
  File "/www/web/django_video/video_omsa/video/views.py", line 157, in up_recive
    save_destination = open(os.path.join("uploads",files.name),'wb+') # 打开特定的文件进行二进制写操作
IOError: [Errno 2] No such file or directory: u'uploads/api.letiku.net.backend.sql'
Internal Server Error: /up_recive
Traceback (most recent call last):
  File "/www/web/django_video/env/lib/python2.7/site-packages/django/core/handlers/base.py", line 149, in get_response
    response = self.process_exception_by_middleware(e, request)
  File "/www/web/django_video/env/lib/python2.7/site-packages/django/core/handlers/base.py", line 147, in get_response
    response = wrapped_callback(request, *callback_args, **callback_kwargs)
  File "/www/web/django_video/video_omsa/video/views.py", line 157, in up_recive
    save_destination = open(os.path.join("uploads",files.name),'wb+') # 打开特定的文件进行二进制写操作
IOError: [Errno 2] No such file or directory: u'uploads/api.letiku.net.backend.sql'
[06/Jul/2017 10:15:51] "POST /up_recive HTTP/1.0" 500 67653
Internal Server Error: /up_recive
Traceback (most recent call last):
  File "/www/web/django_video/env/lib/python2.7/site-packages/django/core/handlers/base.py", line 149, in get_response
    response = self.process_exception_by_middleware(e, request)
  File "/www/web/django_video/env/lib/python2.7/site-packages/django/core/handlers/base.py", line 147, in get_response
    response = wrapped_callback(request, *callback_args, **callback_kwargs)
  File "/www/web/django_video/video_omsa/video/views.py", line 157, in up_recive
    save_destination = open(os.path.join("uploads",files.name),'wb+') # 打开特定的文件进行二进制写操作
IOError: [Errno 2] No such file or directory: u'uploads/api.letiku.net.backend.sql'
Internal Server Error: /up_recive
Traceback (most recent call last):
  File "/www/web/django_video/env/lib/python2.7/site-packages/django/core/handlers/base.py", line 149, in get_response
    response = self.process_exception_by_middleware(e, request)
  File "/www/web/django_video/env/lib/python2.7/site-packages/django/core/handlers/base.py", line 147, in get_response
    response = wrapped_callback(request, *callback_args, **callback_kwargs)
  File "/www/web/django_video/video_omsa/video/views.py", line 157, in up_recive
    save_destination = open(os.path.join("uploads",files.name),'wb+') # 打开特定的文件进行二进制写操作
IOError: [Errno 2] No such file or directory: u'uploads/api.letiku.net.backend.sql'
[06/Jul/2017 10:15:55] "POST /up_recive HTTP/1.0" 500 67653
[06/Jul/2017 10:16:10] "POST /up_recive HTTP/1.0" 200 13
[06/Jul/2017 10:16:41] "GET /inters_data HTTP/1.0" 200 6884
[06/Jul/2017 10:16:53] "POST /inters_data HTTP/1.0" 200 6995
[06/Jul/2017 10:17:55] "POST /inters_data HTTP/1.0" 200 6995
Performing system checks...

System check identified no issues (0 silenced).
July 06, 2017 - 10:15:51
Django version 1.9, using settings 'video_omsa.settings'
Starting development server at http://0.0.0.0:88/
Quit the server with CONTROL-C.
(1064, "You have an error in your SQL syntax; check the manual that corresponds to your MySQL server version for the right syntax to use near 'desclimit 11' at line 1")
(1064, "You have an error in your SQL syntax; check the manual that corresponds to your MySQL server version for the right syntax to use near 'desclimit 11' at line 1")
[06/Jul/2017 10:21:04] "POST /inters_data HTTP/1.0" 200 7008
Performing system checks...

System check identified no issues (0 silenced).
July 06, 2017 - 10:21:00
Django version 1.9, using settings 'video_omsa.settings'
Starting development server at http://0.0.0.0:88/
Quit the server with CONTROL-C.
(1064, "You have an error in your SQL syntax; check the manual that corresponds to your MySQL server version for the right syntax to use near 'desclimit 11' at line 1")
Performing system checks...

System check identified no issues (0 silenced).
July 06, 2017 - 10:22:40
Django version 1.9, using settings 'video_omsa.settings'
Starting development server at http://0.0.0.0:88/
Quit the server with CONTROL-C.
[06/Jul/2017 10:22:50] "POST /inters_data HTTP/1.0" 200 6995
[06/Jul/2017 10:22:58] "POST /inters_data HTTP/1.0" 200 6995
[06/Jul/2017 10:22:59] "POST /inters_data HTTP/1.0" 200 6995
[06/Jul/2017 10:23:00] "POST /inters_data HTTP/1.0" 200 6995
[06/Jul/2017 10:24:51] "POST /inters_data HTTP/1.0" 200 6353
[06/Jul/2017 10:24:53] "GET /inters_data HTTP/1.0" 200 6242
[06/Jul/2017 10:25:02] "POST /inters_data HTTP/1.0" 200 6353
[06/Jul/2017 10:25:41] "GET /inters_data HTTP/1.0" 200 6236
[06/Jul/2017 10:25:57] "GET /inters_data HTTP/1.0" 200 6238
[06/Jul/2017 10:26:07] "POST /inters_data HTTP/1.0" 200 6349
[06/Jul/2017 10:26:22] "GET /inters_data?csrfmiddlewaretoken=KsTz5Rk184SonPGidOACqoaayPWH0Ef0&action=imge&data%5Bd%5D=2017_05_24&data%5Btop%5D=23 HTTP/1.0" 200 0
[06/Jul/2017 10:26:23] "GET /inters_data?csrfmiddlewaretoken=KsTz5Rk184SonPGidOACqoaayPWH0Ef0&action=imge&data%5Bd%5D=2017_05_24&data%5Btop%5D=23 HTTP/1.0" 200 0
[06/Jul/2017 10:26:24] "GET /export_cvs?%5Bobject+Object%5D=%7B%22d%22%3A%222017_05_24%22%2C%22top%22%3A%2223%22%7D HTTP/1.0" 200 24
[06/Jul/2017 10:26:36] "POST /inters_data HTTP/1.0" 200 6349
[06/Jul/2017 10:26:38] "GET /export_cvs?%5Bobject+Object%5D=%7B%22d%22%3A%222017_05_24%22%2C%22top%22%3A%2223%22%7D HTTP/1.0" 200 24
[06/Jul/2017 10:27:38] "GET /export_cvs?%5Bobject+Object%5D=%7B%22d%22%3A%222017_05_24%22%2C%22top%22%3A%2223%22%7D HTTP/1.0" 200 24
[06/Jul/2017 10:28:11] "POST /inters_data HTTP/1.0" 200 6349
[06/Jul/2017 10:28:13] "POST /inters_data HTTP/1.0" 200 6349
[06/Jul/2017 10:28:15] "GET /export_cvs?%5Bobject+Object%5D=%7B%22d%22%3A%222017_06_16%22%2C%22top%22%3A%2223%22%7D HTTP/1.0" 200 24
Performing system checks...

System check identified no issues (0 silenced).
July 06, 2017 - 10:22:46
Django version 1.9, using settings 'video_omsa.settings'
Starting development server at http://0.0.0.0:88/
Quit the server with CONTROL-C.
(1064, "You have an error in your SQL syntax; check the manual that corresponds to your MySQL server version for the right syntax to use near 'desclimit 11' at line 1")
(1064, "You have an error in your SQL syntax; check the manual that corresponds to your MySQL server version for the right syntax to use near 'desclimit 11' at line 1")
(1064, "You have an error in your SQL syntax; check the manual that corresponds to your MySQL server version for the right syntax to use near 'desclimit 11' at line 1")
(1064, "You have an error in your SQL syntax; check the manual that corresponds to your MySQL server version for the right syntax to use near 'desclimit 11' at line 1")
(1064, "You have an error in your SQL syntax; check the manual that corresponds to your MySQL server version for the right syntax to use near 'desclimit 11' at line 1")
(1064, "You have an error in your SQL syntax; check the manual that corresponds to your MySQL server version for the right syntax to use near 'desclimit 23' at line 1")
(1064, "You have an error in your SQL syntax; check the manual that corresponds to your MySQL server version for the right syntax to use near 'desclimit 23' at line 1")
(1064, "You have an error in your SQL syntax; check the manual that corresponds to your MySQL server version for the right syntax to use near 'desclimit 23' at line 1")
(1064, "You have an error in your SQL syntax; check the manual that corresponds to your MySQL server version for the right syntax to use near 'desclimit 23' at line 1")
(1064, "You have an error in your SQL syntax; check the manual that corresponds to your MySQL server version for the right syntax to use near 'desclimit 23' at line 1")
(1064, "You have an error in your SQL syntax; check the manual that corresponds to your MySQL server version for the right syntax to use near 'desclimit 23' at line 1")
(1064, "You have an error in your SQL syntax; check the manual that corresponds to your MySQL server version for the right syntax to use near 'desclimit 23' at line 1")
(1064, "You have an error in your SQL syntax; check the manual that corresponds to your MySQL server version for the right syntax to use near 'desclimit 23' at line 1")
(1064, "You have an error in your SQL syntax; check the manual that corresponds to your MySQL server version for the right syntax to use near 'desclimit 23' at line 1")
(1064, "You have an error in your SQL syntax; check the manual that corresponds to your MySQL server version for the right syntax to use near 'desclimit 23' at line 1")
(1064, "You have an error in your SQL syntax; check the manual that corresponds to your MySQL server version for the right syntax to use near 'desclimit 23' at line 1")
[06/Jul/2017 10:31:32] "GET /inters_data HTTP/1.0" 200 6238
[06/Jul/2017 10:31:34] "POST /inters_data HTTP/1.0" 200 6349
[06/Jul/2017 10:31:36] "GET /export_cvs?%5Bobject+Object%5D=%7B%22d%22%3A%222016_01_01%22%2C%22top%22%3A%2222%22%7D HTTP/1.0" 200 24
[06/Jul/2017 10:31:43] "POST /inters_data HTTP/1.0" 200 6349
Performing system checks...

System check identified no issues (0 silenced).
July 06, 2017 - 10:31:30
Django version 1.9, using settings 'video_omsa.settings'
Starting development server at http://0.0.0.0:88/
Quit the server with CONTROL-C.
(1064, "You have an error in your SQL syntax; check the manual that corresponds to your MySQL server version for the right syntax to use near 'desclimit 22' at line 1")
(1064, "You have an error in your SQL syntax; check the manual that corresponds to your MySQL server version for the right syntax to use near 'desclimit 22' at line 1")
(1064, "You have an error in your SQL syntax; check the manual that corresponds to your MySQL server version for the right syntax to use near 'desclimit 22' at line 1")
